Workbook

Sheet Read Me
A1: Shepparton United vs Echuca (2026 premiers): team stats workbook
A3: Sheet | B3: What it shows
A4: Where to Improve | B4: START HERE. Every stat: United vs Echuca vs league average per game, the gap, both clubs' league rank, and a verdict. Biggest Echuca advantages are at the top.
A5: Season For v Against | B5: Each club's season averages against its own opponents. Shows how much each club out-did (or was out-done by) the teams it played.
A6: United vs Each Opponent | B6: United's average stats against every opponent: own average, opponent's average and the difference.
A7: Echuca vs Each Opponent | B7: The same for Echuca, so you can compare how the premiers handled each club.
A8: United Games For / Against / Diff | B8: Every United game: United's stats, the opponent's stats, and the difference (formulas).
A9: Echuca Games For / Against / Diff | B9: Every Echuca game including their three finals.
A10: League Per Game | B10: All 12 clubs' per-game averages (the base for 'Where to Improve'). United = blue row, Echuca = green row.
A11: League Season Totals | B11: All 12 clubs' season totals. Finals teams played more games, so per-game is the fairer comparison.
A13: How to read it
B14: • 'Higher is better?' (yellow, blue text) says whether a bigger number is good (Y), bad (N, e.g. turnovers), or has no clear direction (?). You can change these; verdicts and shading update.
B15: • 'Gap in std devs' puts every stat on the same scale: 1.0 means the gap is as big as the typical spread between the 12 clubs. Above the threshold on 'Where to Improve' (0.75 by default) = PRIORITY.
B16: • Blue shading = United better, orange/red = Echuca (or the opponent) better.
A18: Data notes
B19: • Source: Premier Data (pdapp2.advancedhp.com.au), Shepparton United club account, scraped 25 Sep 2026. Season complete; Echuca won the grand final.
B20: • United played 18 games (no finals). Echuca's figures include 3 finals, which were against the strongest teams.
B21: • 'Pressure acts' (PRA) and 'Overall pressure' (PR) are different Premier Data measures; both are included.
B22: • Stats recorded as 0 for every club (frees against, bounces, KO) are left out of the league sheets.
B23: • 'Score sources' rows in 'Season For v Against' are Premier Data's scoring breakdown by source (e.g. scores from turnovers); the direction is left as '?'.
B24: • Stat codes GST and KO are not labelled by Premier Data.
A26: Stat codes
A27: 1% | B27: One-percenters
A28: B | B28: Behinds
A29: BOU | B29: Bounces
A30: BTKL | B30: Back 50 tackles
A31: BTO | B31: Back-half turnovers
A32: BUC | B32: Ball-up clearances
A33: C% | B33: Clearance efficiency %
A34: CC | B34: Centre clearances
A35: CM | B35: Contested marks
A36: CP | B36: Contested possessions
A37: Ch | B37: Chases
A38: Cl | B38: Clearances
... A92: UM | B92: Uncontested marks

Sheet Where to Improve
A1: Where Shepparton United needs to improve to play like the premiers (Echuca)
A2: Per-game averages from the 'League Per Game' sheet. Every number below is a formula. Rows are ordered by the size of the gap (biggest Echuca advantage first) as at 25 Sep 2026.
A3: Priority threshold (gap in standard deviations): | F3: 0.75 | G3: ← editable. Yellow cells with blue text are settings you can change.
A5: Stat | B5: Stat name | C5: Higher is better? | D5: United per game | E5: Echuca per game | F5: League average | G5: Gap (Echuca − United) | H5: Gap as % of United | I5: United rank (of 12) | J5: Echuca rank (of 12) | K5: Gap in std devs (+ = Echuca better) | L5: Verdict
A6: LBG | B6: Loose ball gets | C6: Y | D6: =INDEX('League Per Game'!$T$5:$T$16,MATCH("Shepparton United",'League Per Game'!$A$5:$A$16,0)) -> 49.6 | E6: =INDEX('League Per Game'!$T$5:$T$16,MATCH("Echuca",'League Per Game'!$A$5:$A$16,0)) -> 66 | F6: =AVERAGE('League Per Game'!$T$5:$T$16) -> 56.108333 | G6: =E6-D6 -> 16.4 | H6: =IF(D6=0,"",G6/D6) -> 0.33064516 | I6: =IF(C6="N",RANK(D6,'League Per Game'!$T$5:$T$16,1),RANK(D6,'League Per Game'!$T$5:$T$16,0)) -> 12 | J6: =IF(C6="N",RANK(E6,'League Per Game'!$T$5:$T$16,1),RANK(E6,'League Per Game'!$T$5:$T$16,0)) -> 1 | K6: =IF(OR(C6="?",STDEVP('League Per Game'!$T$5:$T$16)=0),"",IF(C6="N",-1,1)*G6/STDEVP('League Per Game'!$T$5:$T$16)) -> 3.2193543 | L6: =IF(K6="","Context only (no clear better direction)",IF(K6>=$F$3,"PRIORITY: Echuca well ahead",IF(K6>0,"Echuca ahead",IF(K6<=-$F$3,"United strength","United ahead or level")))) -> PRIORITY: Echuca well ahead
A7: Sm | B7: Smothers | C7: Y | D7: =INDEX('League Per Game'!$AM$5:$AM$16,MATCH("Shepparton United",'League Per Game'!$A$5:$A$16,0)) -> 3.2 | E7: =INDEX('League Per Game'!$AM$5:$AM$16,MATCH("Echuca",'League Per Game'!$A$5:$A$16,0)) -> 6 | F7: =AVERAGE('League Per Game'!$AM$5:$AM$16) -> 4.3083333 | G7: =E7-D7 -> 2.8 | H7: =IF(D7=0,"",G7/D7) -> 0.875 | I7: =IF(C7="N",RANK(D7,'League Per Game'!$AM$5:$AM$16,1),RANK(D7,'League Per Game'!$AM$5:$AM$16,0)) -> 11 | J7: =IF(C7="N",RANK(E7,'League Per Game'!$AM$5:$AM$16,1),RANK(E7,'League Per Game'!$AM$5:$AM$16,0)) -> 1 | K7: =IF(OR(C7="?",STDEVP('League Per Game'!$AM$5:$AM$16)=0),"",IF(C7="N",-1,1)*G7/STDEVP('League Per Game'!$AM$5:$AM$16)) -> 3.1128463 | L7: =IF(K7="","Context only (no clear better direction)",IF(K7>=$F$3,"PRIORITY: Echuca well ahead",IF(K7>0,"Echuca ahead",IF(K7<=-$F$3,"United strength","United ahead or level")))) -> PRIORITY: Echuca well ahead
A8: TGB | B8: Total groundball gets | C8: Y | D8: =INDEX('League Per Game'!$R$5:$R$16,MATCH("Shepparton United",'League Per Game'!$A$5:$A$16,0)) -> 77.9 | E8: =INDEX('League Per Game'!$R$5:$R$16,MATCH("Echuca",'League Per Game'!$A$5:$A$16,0)) -> 100.2 | F8: =AVERAGE('League Per Game'!$R$5:$R$16) -> 86.916667 | G8: =E8-D8 -> 22.3 | H8: =IF(D8=0,"",G8/D8) -> 0.28626444 | I8: =IF(C8="N",RANK(D8,'League Per Game'!$R$5:$R$16,1),RANK(D8,'League Per Game'!$R$5:$R$16,0)) -> 11 | J8: =IF(C8="N",RANK(E8,'League Per Game'!$R$5:$R$16,1),RANK(E8,'League Per Game'!$R$5:$R$16,0)) -> 1 | K8: =IF(OR(C8="?",STDEVP('League Per Game'!$R$5:$R$16)=0),"",IF(C8="N",-1,1)*G8/STDEVP('League Per Game'!$R$5:$R$16)) -> 3.0782869 | L8: =IF(K8="","Context only (no clear better direction)",IF(K8>=$F$3,"PRIORITY: Echuca well ahead",IF(K8>0,"Echuca ahead",IF(K8<=-$F$3,"United strength","United ahead or level")))) -> PRIORITY: Echuca well ahead
A9: 1% | B9: One-percenters | C9: Y | D9: =INDEX('League Per Game'!$AF$5:$AF$16,MATCH("Shepparton United",'League Per Game'!$A$5:$A$16,0)) -> 36.3 | E9: =INDEX('League Per Game'!$AF$5:$AF$16,MATCH("Echuca",'League Per Game'!$A$5:$A$16,0)) -> 45.4 | F9: =AVERAGE('League Per Game'!$AF$5:$AF$16) -> 43.308333 | G9: =E9-D9 -> 9.1 | H9: =IF(D9=0,"",G9/D9) -> 0.25068871 | I9: =IF(C9="N",RANK(D9,'League Per Game'!$AF$5:$AF$16,1),RANK(D9,'League Per Game'!$AF$5:$AF$16,0)) -> 12 | J9: =IF(C9="N",RANK(E9,'League Per Game'!$AF$5:$AF$16,1),RANK(E9,'League Per Game'!$AF$5:$AF$16,0)) -> 4 | K9: =IF(OR(C9="?",STDEVP('League Per Game'!$AF$5:$AF$16)=0),"",IF(C9="N",-1,1)*G9/STDEVP('League Per Game'!$AF$5:$AF$16)) -> 2.7803366 | L9: =IF(K9="","Context only (no clear better direction)",IF(K9>=$F$3,"PRIORITY: Echuca well ahead",IF(K9>0,"Echuca ahead",IF(K9<=-$F$3,"United strength","United ahead or level")))) -> PRIORITY: Echuca well ahead
A10: CP | B10: Contested possessions | C10: Y | D10: =INDEX('League Per Game'!$G$5:$G$16,MATCH("Shepparton United",'League Per Game'!$A$5:$A$16,0)) -> 128.9 | E10: =INDEX('League Per Game'!$G$5:$G$16,MATCH("Echuca",'League Per Game'!$A$5:$A$16,0)) -> 152.9 | F10: =AVERAGE('League Per Game'!$G$5:$G$16) -> 136.55833 | G10: =E10-D10 -> 24 | H10: =IF(D10=0,"",G10/D10) -> 0.18619085 | I10: =IF(C10="N",RANK(D10,'League Per Game'!$G$5:$G$16,1),RANK(D10,'League Per Game'!$G$5:$G$16,0)) -> 8 | J10: =IF(C10="N",RANK(E10,'League Per Game'!$G$5:$G$16,1),RANK(E10,'League Per Game'!$G$5:$G$16,0)) -> 1 | K10: =IF(OR(C10="?",STDEVP('League Per Game'!$G$5:$G$16)=0),"",IF(C10="N",-1,1)*G10/STDEVP('League Per Game'!$G$5:$G$16)) -> 2.6100462 | L10: =IF(K10="","Context only (no clear better direction)",IF(K10>=$F$3,"PRIORITY: Echuca well ahead",IF(K10>0,"Echuca ahead",IF(K10<=-$F$3,"United strength","United ahead or level")))) -> PRIORITY: Echuca well ahead
A11: PR | B11: Overall pressure | C11: Y | D11: =INDEX('League Per Game'!$AK$5:$AK$16,MATCH("Shepparton United",'League Per Game'!$A$5:$A$16,0)) -> 105.2 | E11: =INDEX('League Per Game'!$AK$5:$AK$16,MATCH("Echuca",'League Per Game'!$A$5:$A$16,0)) -> 129.4 | F11: =AVERAGE('League Per Game'!$AK$5:$AK$16) -> 124.21667 | G11: =E11-D11 -> 24.2 | H11: =IF(D11=0,"",G11/D11) -> 0.23003802 | I11: =IF(C11="N",RANK(D11,'League Per Game'!$AK$5:$AK$16,1),RANK(D11,'League Per Game'!$AK$5:$AK$16,0)) -> 12 | J11: =IF(C11="N",RANK(E11,'League Per Game'!$AK$5:$AK$16,1),RANK(E11,'League Per Game'!$AK$5:$AK$16,0)) -> 5 | K11: =IF(OR(C11="?",STDEVP('League Per Game'!$AK$5:$AK$16)=0),"",IF(C11="N",-1,1)*G11/STDEVP('League Per Game'!$AK$5:$AK$16)) -> 2.5195616 | L11: =IF(K11="","Context only (no clear better direction)",IF(K11>=$F$3,"PRIORITY: Echuca well ahead",IF(K11>0,"Echuca ahead",IF(K11<=-$F$3,"United strength","United ahead or level")))) -> PRIORITY: Echuca well ahead
A12: Sp | B12: Spoils | C12: Y | D12: =INDEX('League Per Game'!$AN$5:$AN$16,MATCH("Shepparton United",'League Per Game'!$A$5:$A$16,0)) -> 13.7 | E12: =INDEX('League Per Game'!$AN$5:$AN$16,MATCH("Echuca",'League Per Game'!$A$5:$A$16,0)) -> 19.4 | F12: =AVERAGE('League Per Game'!$AN$5:$AN$16) -> 17.691667 | G12: =E12-D12 -> 5.7 | H12: =IF(D12=0,"",G12/D12) -> 0.41605839 | I12: =IF(C12="N",RANK(D12,'League Per Game'!$AN$5:$AN$16,1),RANK(D12,'League Per Game'!$AN$5:$AN$16,0)) -> 12 | J12: =IF(C12="N",RANK(E12,'League Per Game'!$AN$5:$AN$16,1),RANK(E12,'League Per Game'!$AN$5:$AN$16,0)) -> 4 | K12: =IF(OR(C12="?",STDEVP('League Per Game'!$AN$5:$AN$16)=0),"",IF(C12="N",-1,1)*G12/STDEVP('League Per Game'!$AN$5:$AN$16)) -> 2.3915061 | L12: =IF(K12="","Context only (no clear better direction)",IF(K12>=$F$3,"PRIORITY: Echuca well ahead",IF(K12>0,"Echuca ahead",IF(K12<=-$F$3,"United strength","United ahead or level")))) -> PRIORITY: Echuca well ahead
A13: MTKL | B13: Midfield tackles | C13: Y | D13: =INDEX('League Per Game'!$AP$5:$AP$16,MATCH("Shepparton United",'League Per Game'!$A$5:$A$16,0)) -> 34.3 | E13: =INDEX('League Per Game'!$AP$5:$AP$16,MATCH("Echuca",'League Per Game'!$A$5:$A$16,0)) -> 42.9 | F13: =AVERAGE('League Per Game'!$AP$5:$AP$16) -> 38.191667 | G13: =E13-D13 -> 8.6 | H13: =IF(D13=0,"",G13/D13) -> 0.25072886 | I13: =IF(C13="N",RANK(D13,'League Per Game'!$AP$5:$AP$16,1),RANK(D13,'League Per Game'!$AP$5:$AP$16,0)) -> 10 | J13: =IF(C13="N",RANK(E13,'League Per Game'!$AP$5:$AP$16,1),RANK(E13,'League Per Game'!$AP$5:$AP$16,0)) -> 2 | K13: =IF(OR(C13="?",STDEVP('League Per Game'!$AP$5:$AP$16)=0),"",IF(C13="N",-1,1)*G13/STDEVP('League Per Game'!$AP$5:$AP$16)) -> 2.2876523 | L13: =IF(K13="","Context only (no clear better direction)",IF(K13>=$F$3,"PRIORITY: Echuca well ahead",IF(K13>0,"Echuca ahead",IF(K13<=-$F$3,"United strength","United ahead or level")))) -> PRIORITY: Echuca well ahead
A14: TIC | B14: Throw-in clearances | C14: Y | D14: =INDEX('League Per Game'!$AB$5:$AB$16,MATCH("Shepparton United",'League Per Game'!$A$5:$A$16,0)) -> 11.7 | E14: =INDEX('League Per Game'!$AB$5:$AB$16,MATCH("Echuca",'League Per Game'!$A$5:$A$16,0)) -> 12.8 | F14: =AVERAGE('League Per Game'!$AB$5:$AB$16) -> 12.633333 | G14: =E14-D14 -> 1.1 | H14: =IF(D14=0,"",G14/D14) -> 0.094017094 | I14: =IF(C14="N",RANK(D14,'League Per Game'!$AB$5:$AB$16,1),RANK(D14,'League Per Game'!$AB$5:$AB$16,0)) -> 12 | J14: =IF(C14="N",RANK(E14,'League Per Game'!$AB$5:$AB$16,1),RANK(E14,'League Per Game'!$AB$5:$AB$16,0)) -> 4 | K14: =IF(OR(C14="?",STDEVP('League Per Game'!$AB$5:$AB$16)=0),"",IF(C14="N",-1,1)*G14/STDEVP('League Per Game'!$AB$5:$AB$16)) -> 1.9428579 | L14: =IF(K14="","Context only (no clear better direction)",IF(K14>=$F$3,"PRIORITY: Echuca well ahead",IF(K14>0,"Echuca ahead",IF(K14<=-$F$3,"United strength","United ahead or level")))) -> PRIORITY: Echuca well ahead
A15: T | B15: Tackles | C15: Y | D15: =INDEX('League Per Game'!$O$5:$O$16,MATCH("Shepparton United",'League Per Game'!$A$5:$A$16,0)) -> 55.2 | E15: =INDEX('League Per Game'!$O$5:$O$16,MATCH("Echuca",'League Per Game'!$A$5:$A$16,0)) -> 66 | F15: =AVERAGE('League Per Game'!$O$5:$O$16) -> 62.033333 | G15: =E15-D15 -> 10.8 | H15: =IF(D15=0,"",G15/D15) -> 0.19565217 | I15: =IF(C15="N",RANK(D15,'League Per Game'!$O$5:$O$16,1),RANK(D15,'League Per Game'!$O$5:$O$16,0)) -> 10 | J15: =IF(C15="N",RANK(E15,'League Per Game'!$O$5:$O$16,1),RANK(E15,'League Per Game'!$O$5:$O$16,0)) -> 4 | K15: =IF(OR(C15="?",STDEVP('League Per Game'!$O$5:$O$16)=0),"",IF(C15="N",-1,1)*G15/STDEVP('League Per Game'!$O$5:$O$16)) -> 1.7671968 | L15: =IF(K15="","Context only (no clear better direction)",IF(K15>=$F$3,"PRIORITY: Echuca well ahead",IF(K15>0,"Echuca ahead",IF(K15<=-$F$3,"United strength","United ahead or level")))) -> PRIORITY: Echuca well ahead
A16: HB | B16: Handballs | C16: Y | D16: =INDEX('League Per Game'!$F$5:$F$16,MATCH("Shepparton United",'League Per Game'!$A$5:$A$16,0)) -> 125.4 | E16: =INDEX('League Per Game'!$F$5:$F$16,MATCH("Echuca",'League Per Game'!$A$5:$A$16,0)) -> 142.5 | F16: =AVERAGE('League Per Game'!$F$5:$F$16) -> 129.74167 | G16: =E16-D16 -> 17.1 | H16: =IF(D16=0,"",G16/D16) -> 0.13636364 | I16: =IF(C16="N",RANK(D16,'League Per Game'!$F$5:$F$16,1),RANK(D16,'League Per Game'!$F$5:$F$16,0)) -> 8 | J16: =IF(C16="N",RANK(E16,'League Per Game'!$F$5:$F$16,1),RANK(E16,'League Per Game'!$F$5:$F$16,0)) -> 1 | K16: =IF(OR(C16="?",STDEVP('League Per Game'!$F$5:$F$16)=0),"",IF(C16="N",-1,1)*G16/STDEVP('League Per Game'!$F$5:$F$16)) -> 1.7626765 | L16: =IF(K16="","Context only (no clear better direction)",IF(K16>=$F$3,"PRIORITY: Echuca well ahead",IF(K16>0,"Echuca ahead",IF(K16<=-$F$3,"United strength","United ahead or level")))) -> PRIORITY: Echuca well ahead
A17: HBG | B17: Hard ball gets | C17: Y | D17: =INDEX('League Per Game'!$S$5:$S$16,MATCH("Shepparton United",'League Per Game'!$A$5:$A$16,0)) -> 28.4 | E17: =INDEX('League Per Game'!$S$5:$S$16,MATCH("Echuca",'League Per Game'!$A$5:$A$16,0)) -> 34.1 | F17: =AVERAGE('League Per Game'!$S$5:$S$16) -> 30.816667 | G17: =E17-D17 -> 5.7 | H17: =IF(D17=0,"",G17/D17) -> 0.20070423 | I17: =IF(C17="N",RANK(D17,'League Per Game'!$S$5:$S$16,1),RANK(D17,'League Per Game'!$S$5:$S$16,0)) -> 9 | J17: =IF(C17="N",RANK(E17,'League Per Game'!$S$5:$S$16,1),RANK(E17,'League Per Game'!$S$5:$S$16,0)) -> 2 | K17: =IF(OR(C17="?",STDEVP('League Per Game'!$S$5:$S$16)=0),"",IF(C17="N",-1,1)*G17/STDEVP('League Per Game'!$S$5:$S$16)) -> 1.7292809 | L17: =IF(K17="","Context only (no clear better direction)",IF(K17>=$F$3,"PRIORITY: Echuca well ahead",IF(K17>0,"Echuca ahead",IF(K17<=-$F$3,"United strength","United ahead or level")))) -> PRIORITY: Echuca well ahead
A18: GA% | B18: Goal accuracy % | C18: Y | D18: =INDEX('League Per Game'!$AS$5:$AS$16,MATCH("Shepparton United",'League Per Game'!$A$5:$A$16,0)) -> 50 | E18: =INDEX('League Per Game'!$AS$5:$AS$16,MATCH("Echuca",'League Per Game'!$A$5:$A$16,0)) -> 53 | F18: =AVERAGE('League Per Game'!$AS$5:$AS$16) -> 49.666667 | G18: =E18-D18 -> 3 | H18: =IF(D18=0,"",G18/D18) -> 0.06 | I18: =IF(C18="N",RANK(D18,'League Per Game'!$AS$5:$AS$16,1),RANK(D18,'League Per Game'!$AS$5:$AS$16,0)) -> 4 | J18: =IF(C18="N",RANK(E18,'League Per Game'!$AS$5:$AS$16,1),RANK(E18,'League Per Game'!$AS$5:$AS$16,0)) -> 1 | K18: =IF(OR(C18="?",STDEVP('League Per Game'!$AS$5:$AS$16)=0),"",IF(C18="N",-1,1)*G18/STDEVP('League Per Game'!$AS$5:$AS$16)) -> 1.671258 | L18: =IF(K18="","Context only (no clear better direction)",IF(K18>=$F$3,"PRIORITY: Echuca well ahead",IF(K18>0,"Echuca ahead",IF(K18<=-$F$3,"United strength","United ahead or level")))) -> PRIORITY: Echuca well ahead
A19: IP | B19: Intercept possessions | C19: Y | D19: =INDEX('League Per Game'!$N$5:$N$16,MATCH("Shepparton United",'League Per Game'!$A$5:$A$16,0)) -> 68.3 | E19: =INDEX('League Per Game'!$N$5:$N$16,MATCH("Echuca",'League Per Game'!$A$5:$A$16,0)) -> 74.2 | F19: =AVERAGE('League Per Game'!$N$5:$N$16) -> 70.15 | G19: =E19-D19 -> 5.9 | H19: =IF(D19=0,"",G19/D19) -> 0.086383602 | I19: =IF(C19="N",RANK(D19,'League Per Game'!$N$5:$N$16,1),RANK(D19,'League Per Game'!$N$5:$N$16,0)) -> 8 | J19: =IF(C19="N",RANK(E19,'League Per Game'!$N$5:$N$16,1),RANK(E19,'League Per Game'!$N$5:$N$16,0)) -> 2 | K19: =IF(OR(C19="?",STDEVP('League Per Game'!$N$5:$N$16)=0),"",IF(C19="N",-1,1)*G19/STDEVP('League Per Game'!$N$5:$N$16)) -> 1.51419 | L19: =IF(K19="","Context only (no clear better direction)",IF(K19>=$F$3,"PRIORITY: Echuca well ahead",IF(K19>0,"Echuca ahead",IF(K19<=-$F$3,"United strength","United ahead or level")))) -> PRIORITY: Echuca well ahead
A20: GA | B20: Goal assists | C20: Y | D20: =INDEX('League Per Game'!$AR$5:$AR$16,MATCH("Shepparton United",'League Per Game'!$A$5:$A$16,0)) -> 9.7 | E20: =INDEX('League Per Game'!$AR$5:$AR$16,MATCH("Echuca",'League Per Game'!$A$5:$A$16,0)) -> 13.1 | F20: =AVERAGE('League Per Game'!$AR$5:$AR$16) -> 9.2583333 | G20: =E20-D20 -> 3.4 | H20: =IF(D20=0,"",G20/D20) -> 0.35051546 | I20: =IF(C20="N",RANK(D20,'League Per Game'!$AR$5:$AR$16,1),RANK(D20,'League Per Game'!$AR$5:$AR$16,0)) -> 6 | J20: =IF(C20="N",RANK(E20,'League Per Game'!$AR$5:$AR$16,1),RANK(E20,'League Per Game'!$AR$5:$AR$16,0)) -> 1 | K20: =IF(OR(C20="?",STDEVP('League Per Game'!$AR$5:$AR$16)=0),"",IF(C20="N",-1,1)*G20/STDEVP('League Per Game'!$AR$5:$AR$16)) -> 1.4849525 | L20: =IF(K20="","Context only (no clear better direction)",IF(K20>=$F$3,"PRIORITY: Echuca well ahead",IF(K20>0,"Echuca ahead",IF(K20<=-$F$3,"United strength","United ahead or level")))) -> PRIORITY: Echuca well ahead
A21: H% | B21: Handball efficiency % | C21: Y | D21: =INDEX('League Per Game'!$AV$5:$AV$16,MATCH("Shepparton United",'League Per Game'!$A$5:$A$16,0)) -> 77 | E21: =INDEX('League Per Game'!$AV$5:$AV$16,MATCH("Echuca",'League Per Game'!$A$5:$A$16,0)) -> 79 | F21: =AVERAGE('League Per Game'!$AV$5:$AV$16) -> 77.666667 | G21: =E21-D21 -> 2 | H21: =IF(D21=0,"",G21/D21) -> 0.025974026 | I21: =IF(C21="N",RANK(D21,'League Per Game'!$AV$5:$AV$16,1),RANK(D21,'League Per Game'!$AV$5:$AV$16,0)) -> 9 | J21: =IF(C21="N",RANK(E21,'League Per Game'!$AV$5:$AV$16,1),RANK(E21,'League Per Game'!$AV$5:$AV$16,0)) -> 1 | K21: =IF(OR(C21="?",STDEVP('League Per Game'!$AV$5:$AV$16)=0),"",IF(C21="N",-1,1)*G21/STDEVP('League Per Game'!$AV$5:$AV$16)) -> 1.3949717 | L21: =IF(K21="","Context only (no clear better direction)",IF(K21>=$F$3,"PRIORITY: Echuca well ahead",IF(K21>0,"Echuca ahead",IF(K21<=-$F$3,"United strength","United ahead or level")))) -> PRIORITY: Echuca well ahead
A22: G | B22: Goals | C22: Y | D22: =INDEX('League Per Game'!$K$5:$K$16,MATCH("Shepparton United",'League Per Game'!$A$5:$A$16,0)) -> 11.6 | E22: =INDEX('League Per Game'!$K$5:$K$16,MATCH("Echuca",'League Per Game'!$A$5:$A$16,0)) -> 14.8 | F22: =AVERAGE('League Per Game'!$K$5:$K$16) -> 10.975 | G22: =E22-D22 -> 3.2 | H22: =IF(D22=0,"",G22/D22) -> 0.27586207 | I22: =IF(C22="N",RANK(D22,'League Per Game'!$K$5:$K$16,1),RANK(D22,'League Per Game'!$K$5:$K$16,0)) -> 6 | J22: =IF(C22="N",RANK(E22,'League Per Game'!$K$5:$K$16,1),RANK(E22,'League Per Game'!$K$5:$K$16,0)) -> 1 | K22: =IF(OR(C22="?",STDEVP('League Per Game'!$K$5:$K$16)=0),"",IF(C22="N",-1,1)*G22/STDEVP('League Per Game'!$K$5:$K$16)) -> 1.2639035 | L22: =IF(K22="","Context only (no clear better direction)",IF(K22>=$F$3,"PRIORITY: Echuca well ahead",IF(K22>0,"Echuca ahead",IF(K22<=-$F$3,"United strength","United ahead or level")))) -> PRIORITY: Echuca well ahead
A23: D | B23: Disposals | C23: Y | D23: =INDEX('League Per Game'!$D$5:$D$16,MATCH("Shepparton United",'League Per Game'!$A$5:$A$16,0)) -> 349.7 | E23: =INDEX('League Per Game'!$D$5:$D$16,MATCH("Echuca",'League Per Game'!$A$5:$A$16,0)) -> 372.4 | F23: =AVERAGE('League Per Game'!$D$5:$D$16) -> 339.38333 | G23: =E23-D23 -> 22.7 | H23: =IF(D23=0,"",G23/D23) -> 0.064912782 | I23: =IF(C23="N",RANK(D23,'League Per Game'!$D$5:$D$16,1),RANK(D23,'League Per Game'!$D$5:$D$16,0)) -> 4 | J23: =IF(C23="N",RANK(E23,'League Per Game'!$D$5:$D$16,1),RANK(E23,'League Per Game'!$D$5:$D$16,0)) -> 2 | K23: =IF(OR(C23="?",STDEVP('League Per Game'!$D$5:$D$16)=0),"",IF(C23="N",-1,1)*G23/STDEVP('League Per Game'!$D$5:$D$16)) -> 1.2213724 | L23: =IF(K23="","Context only (no clear better direction)",IF(K23>=$F$3,"PRIORITY: Echuca well ahead",IF(K23>0,"Echuca ahead",IF(K23<=-$F$3,"United strength","United ahead or level")))) -> PRIORITY: Echuca well ahead
A24: RP | B24: Ranking points (Premier Data impact score) | C24: Y | D24: =INDEX('League Per Game'!$C$5:$C$16,MATCH("Shepparton United",'League Per Game'!$A$5:$A$16,0)) -> 1617.7 | E24: =INDEX('League Per Game'!$C$5:$C$16,MATCH("Echuca",'League Per Game'!$A$5:$A$16,0)) -> 1739.5 | F24: =AVERAGE('League Per Game'!$C$5:$C$16) -> 1572.3667 | G24: =E24-D24 -> 121.8 | H24: =IF(D24=0,"",G24/D24) -> 0.075292081 | I24: =IF(C24="N",RANK(D24,'League Per Game'!$C$5:$C$16,1),RANK(D24,'League Per Game'!$C$5:$C$16,0)) -> 4 | J24: =IF(C24="N",RANK(E24,'League Per Game'!$C$5:$C$16,1),RANK(E24,'League Per Game'!$C$5:$C$16,0)) -> 1 | K24: =IF(OR(C24="?",STDEVP('League Per Game'!$C$5:$C$16)=0),"",IF(C24="N",-1,1)*G24/STDEVP('League Per Game'!$C$5:$C$16)) -> 1.1621605 | L24: =IF(K24="","Context only (no clear better direction)",IF(K24>=$F$3,"PRIORITY: Echuca well ahead",IF(K24>0,"Echuca ahead",IF(K24<=-$F$3,"United strength","United ahead or level")))) -> PRIORITY: Echuca well ahead
A25: I50% | B25: Inside-50 efficiency % | C25: Y | D25: =INDEX('League Per Game'!$AW$5:$AW$16,MATCH("Shepparton United",'League Per Game'!$A$5:$A$16,0)) -> 51 | E25: =INDEX('League Per Game'!$AW$5:$AW$16,MATCH("Echuca",'League Per Game'!$A$5:$A$16,0)) -> 54 | F25: =AVERAGE('League Per Game'!$AW$5:$AW$16) -> 49.416667 | G25: =E25-D25 -> 3 | H25: =IF(D25=0,"",G25/D25) -> 0.058823529 | I25: =IF(C25="N",RANK(D25,'League Per Game'!$AW$5:$AW$16,1),RANK(D25,'League Per Game'!$AW$5:$AW$16,0)) -> 2 | J25: =IF(C25="N",RANK(E25,'League Per Game'!$AW$5:$AW$16,1),RANK(E25,'League Per Game'!$AW$5:$AW$16,0)) -> 1 | K25: =IF(OR(C25="?",STDEVP('League Per Game'!$AW$5:$AW$16)=0),"",IF(C25="N",-1,1)*G25/STDEVP('League Per Game'!$AW$5:$AW$16)) -> 1.0899087 | L25: =IF(K25="","Context only (no clear better direction)",IF(K25>=$F$3,"PRIORITY: Echuca well ahead",IF(K25>0,"Echuca ahead",IF(K25<=-$F$3,"United strength","United ahead or level")))) -> PRIORITY: Echuca well ahead
A26: C% | B26: Clearance efficiency % | C26: Y | D26: =INDEX('League Per Game'!$AX$5:$AX$16,MATCH("Shepparton United",'League Per Game'!$A$5:$A$16,0)) -> 61 | E26: =INDEX('League Per Game'!$AX$5:$AX$16,MATCH("Echuca",'League Per Game'!$A$5:$A$16,0)) -> 64 | F26: =AVERAGE('League Per Game'!$AX$5:$AX$16) -> 61.583333 | G26: =E26-D26 -> 3 | H26: =IF(D26=0,"",G26/D26) -> 0.049180328 | I26: =IF(C26="N",RANK(D26,'League Per Game'!$AX$5:$AX$16,1),RANK(D26,'League Per Game'!$AX$5:$AX$16,0)) -> 7 | J26: =IF(C26="N",RANK(E26,'League Per Game'!$AX$5:$AX$16,1),RANK(E26,'League Per Game'!$AX$5:$AX$16,0)) -> 3 | K26: =IF(OR(C26="?",STDEVP('League Per Game'!$AX$5:$AX$16)=0),"",IF(C26="N",-1,1)*G26/STDEVP('League Per Game'!$AX$5:$AX$16)) -> 1.0666959 | L26: =IF(K26="","Context only (no clear better direction)",IF(K26>=$F$3,"PRIORITY: Echuca well ahead",IF(K26>0,"Echuca ahead",IF(K26<=-$F$3,"United strength","United ahead or level")))) -> PRIORITY: Echuca well ahead
A27: I50 | B27: Inside 50s | C27: Y | D27: =INDEX('League Per Game'!$J$5:$J$16,MATCH("Shepparton United",'League Per Game'!$A$5:$A$16,0)) -> 48.3 | E27: =INDEX('League Per Game'!$J$5:$J$16,MATCH("Echuca",'League Per Game'!$A$5:$A$16,0)) -> 55.6 | F27: =AVERAGE('League Per Game'!$J$5:$J$16) -> 47.008333 | G27: =E27-D27 -> 7.3 | H27: =IF(D27=0,"",G27/D27) -> 0.15113872 | I27: =IF(C27="N",RANK(D27,'League Per Game'!$J$5:$J$16,1),RANK(D27,'League Per Game'!$J$5:$J$16,0)) -> 7 | J27: =IF(C27="N",RANK(E27,'League Per Game'!$J$5:$J$16,1),RANK(E27,'League Per Game'!$J$5:$J$16,0)) -> 1 | K27: =IF(OR(C27="?",STDEVP('League Per Game'!$J$5:$J$16)=0),"",IF(C27="N",-1,1)*G27/STDEVP('League Per Game'!$J$5:$J$16)) -> 1.0010579 | L27: =IF(K27="","Context only (no clear better direction)",IF(K27>=$F$3,"PRIORITY: Echuca well ahead",IF(K27>0,"Echuca ahead",IF(K27<=-$F$3,"United strength","United ahead or level")))) -> PRIORITY: Echuca well ahead
A28: SI | B28: Score involvements | C28: Y | D28: =INDEX('League Per Game'!$M$5:$M$16,MATCH("Shepparton United",'League Per Game'!$A$5:$A$16,0)) -> 84.4 | E28: =INDEX('League Per Game'!$M$5:$M$16,MATCH("Echuca",'League Per Game'!$A$5:$A$16,0)) -> 100.1 | F28: =AVERAGE('League Per Game'!$M$5:$M$16) -> 75.95 | G28: =E28-D28 -> 15.7 | H28: =IF(D28=0,"",G28/D28) -> 0.18601896 | I28: =IF(C28="N",RANK(D28,'League Per Game'!$M$5:$M$16,1),RANK(D28,'League Per Game'!$M$5:$M$16,0)) -> 5 | J28: =IF(C28="N",RANK(E28,'League Per Game'!$M$5:$M$16,1),RANK(E28,'League Per Game'!$M$5:$M$16,0)) -> 1 | K28: =IF(OR(C28="?",STDEVP('League Per Game'!$M$5:$M$16)=0),"",IF(C28="N",-1,1)*G28/STDEVP('League Per Game'!$M$5:$M$16)) -> 0.95142051 | L28: =IF(K28="","Context only (no clear better direction)",IF(K28>=$F$3,"PRIORITY: Echuca well ahead",IF(K28>0,"Echuca ahead",IF(K28<=-$F$3,"United strength","United ahead or level")))) -> PRIORITY: Echuca well ahead
A29: CC | B29: Centre clearances | C29: Y | D29: =INDEX('League Per Game'!$Z$5:$Z$16,MATCH("Shepparton United",'League Per Game'!$A$5:$A$16,0)) -> 10 | E29: =INDEX('League Per Game'!$Z$5:$Z$16,MATCH("Echuca",'League Per Game'!$A$5:$A$16,0)) -> 10.8 | F29: =AVERAGE('League Per Game'!$Z$5:$Z$16) -> 10.233333 | G29: =E29-D29 -> 0.8 | H29: =IF(D29=0,"",G29/D29) -> 0.08 | I29: =IF(C29="N",RANK(D29,'League Per Game'!$Z$5:$Z$16,1),RANK(D29,'League Per Game'!$Z$5:$Z$16,0)) -> 7 | J29: =IF(C29="N",RANK(E29,'League Per Game'!$Z$5:$Z$16,1),RANK(E29,'League Per Game'!$Z$5:$Z$16,0)) -> 5 | K29: =IF(OR(C29="?",STDEVP('League Per Game'!$Z$5:$Z$16)=0),"",IF(C29="N",-1,1)*G29/STDEVP('League Per Game'!$Z$5:$Z$16)) -> 0.72911626 | L29: =IF(K29="","Context only (no clear better direction)",IF(K29>=$F$3,"PRIORITY: Echuca well ahead",IF(K29>0,"Echuca ahead",IF(K29<=-$F$3,"United strength","United ahead or level")))) -> Echuca ahead
A30: CM | B30: Contested marks | C30: Y | D30: =INDEX('League Per Game'!$V$5:$V$16,MATCH("Shepparton United",'League Per Game'!$A$5:$A$16,0)) -> 14.3 | E30: =INDEX('League Per Game'!$V$5:$V$16,MATCH("Echuca",'League Per Game'!$A$5:$A$16,0)) -> 15.4 | F30: =AVERAGE('League Per Game'!$V$5:$V$16) -> 13.283333 | G30: =E30-D30 -> 1.1 | H30: =IF(D30=0,"",G30/D30) -> 0.076923077 | I30: =IF(C30="N",RANK(D30,'League Per Game'!$V$5:$V$16,1),RANK(D30,'League Per Game'!$V$5:$V$16,0)) -> 4 | J30: =IF(C30="N",RANK(E30,'League Per Game'!$V$5:$V$16,1),RANK(E30,'League Per Game'!$V$5:$V$16,0)) -> 2 | K30: =IF(OR(C30="?",STDEVP('League Per Game'!$V$5:$V$16)=0),"",IF(C30="N",-1,1)*G30/STDEVP('League Per Game'!$V$5:$V$16)) -> 0.64375693 | L30: =IF(K30="","Context only (no clear better direction)",IF(K30>=$F$3,"PRIORITY: Echuca well ahead",IF(K30>0,"Echuca ahead",IF(K30<=-$F$3,"United strength","United ahead or level")))) -> Echuca ahead
A31: Cl | B31: Clearances | C31: Y | D31: =INDEX('League Per Game'!$I$5:$I$16,MATCH("Shepparton United",'League Per Game'!$A$5:$A$16,0)) -> 41.8 | E31: =INDEX('League Per Game'!$I$5:$I$16,MATCH("Echuca",'League Per Game'!$A$5:$A$16,0)) -> 43.6 | F31: =AVERAGE('League Per Game'!$I$5:$I$16) -> 42.316667 | G31: =E31-D31 -> 1.8 | H31: =IF(D31=0,"",G31/D31) -> 0.043062201 | I31: =IF(C31="N",RANK(D31,'League Per Game'!$I$5:$I$16,1),RANK(D31,'League Per Game'!$I$5:$I$16,0)) -> 8 | J31: =IF(C31="N",RANK(E31,'League Per Game'!$I$5:$I$16,1),RANK(E31,'League Per Game'!$I$5:$I$16,0)) -> 6 | K31: =IF(OR(C31="?",STDEVP('League Per Game'!$I$5:$I$16)=0),"",IF(C31="N",-1,1)*G31/STDEVP('League Per Game'!$I$5:$I$16)) -> 0.59211203 | L31: =IF(K31="","Context only (no clear better direction)",IF(K31>=$F$3,"PRIORITY: Echuca well ahead",IF(K31>0,"Echuca ahead",IF(K31<=-$F$3,"United strength","United ahead or level")))) -> Echuca ahead
A32: FTKL | B32: Forward 50 tackles | C32: Y | D32: =INDEX('League Per Game'!$AO$5:$AO$16,MATCH("Shepparton United",'League Per Game'!$A$5:$A$16,0)) -> 10.2 | E32: =INDEX('League Per Game'!$AO$5:$AO$16,MATCH("Echuca",'League Per Game'!$A$5:$A$16,0)) -> 11.5 | F32: =AVERAGE('League Per Game'!$AO$5:$AO$16) -> 11.066667 | G32: =E32-D32 -> 1.3 | H32: =IF(D32=0,"",G32/D32) -> 0.12745098 | I32: =IF(C32="N",RANK(D32,'League Per Game'!$AO$5:$AO$16,1),RANK(D32,'League Per Game'!$AO$5:$AO$16,0)) -> 9 | J32: =IF(C32="N",RANK(E32,'League Per Game'!$AO$5:$AO$16,1),RANK(E32,'League Per Game'!$AO$5:$AO$16,0)) -> 6 | K32: =IF(OR(C32="?",STDEVP('League Per Game'!$AO$5:$AO$16)=0),"",IF(C32="N",-1,1)*G32/STDEVP('League Per Game'!$AO$5:$AO$16)) -> 0.5590572 | L32: =IF(K32="","Context only (no clear better direction)",IF(K32>=$F$3,"PRIORITY: Echuca well ahead",IF(K32>0,"Echuca ahead",IF(K32<=-$F$3,"United strength","United ahead or level")))) -> Echuca ahead
A33: BTKL | B33: Back 50 tackles | C33: Y | D33: =INDEX('League Per Game'!$AQ$5:$AQ$16,MATCH("Shepparton United",'League Per Game'!$A$5:$A$16,0)) -> 10.6 | E33: =INDEX('League Per Game'!$AQ$5:$AQ$16,MATCH("Echuca",'League Per Game'!$A$5:$A$16,0)) -> 11.6 | F33: =AVERAGE('League Per Game'!$AQ$5:$AQ$16) -> 12.783333 | G33: =E33-D33 -> 1 | H33: =IF(D33=0,"",G33/D33) -> 0.094339623 | I33: =IF(C33="N",RANK(D33,'League Per Game'!$AQ$5:$AQ$16,1),RANK(D33,'League Per Game'!$AQ$5:$AQ$16,0)) -> 11 | J33: =IF(C33="N",RANK(E33,'League Per Game'!$AQ$5:$AQ$16,1),RANK(E33,'League Per Game'!$AQ$5:$AQ$16,0)) -> 8 | K33: =IF(OR(C33="?",STDEVP('League Per Game'!$AQ$5:$AQ$16)=0),"",IF(C33="N",-1,1)*G33/STDEVP('League Per Game'!$AQ$5:$AQ$16)) -> 0.44955488 | L33: =IF(K33="","Context only (no clear better direction)",IF(K33>=$F$3,"PRIORITY: Echuca well ahead",IF(K33>0,"Echuca ahead",IF(K33<=-$F$3,"United strength","United ahead or level")))) -> Echuca ahead
A34: K | B34: Kicks | C34: Y | D34: =INDEX('League Per Game'!$E$5:$E$16,MATCH("Shepparton United",'League Per Game'!$A$5:$A$16,0)) -> 224.3 | E34: =INDEX('League Per Game'!$E$5:$E$16,MATCH("Echuca",'League Per Game'!$A$5:$A$16,0)) -> 229.9 | F34: =AVERAGE('League Per Game'!$E$5:$E$16) -> 209.65 | G34: =E34-D34 -> 5.6 | H34: =IF(D34=0,"",G34/D34) -> 0.024966563 | I34: =IF(C34="N",RANK(D34,'League Per Game'!$E$5:$E$16,1),RANK(D34,'League Per Game'!$E$5:$E$16,0)) -> 3 | J34: =IF(C34="N",RANK(E34,'League Per Game'!$E$5:$E$16,1),RANK(E34,'League Per Game'!$E$5:$E$16,0)) -> 2 | K34: =IF(OR(C34="?",STDEVP('League Per Game'!$E$5:$E$16)=0),"",IF(C34="N",-1,1)*G34/STDEVP('League Per Game'!$E$5:$E$16)) -> 0.42972901 | L34: =IF(K34="","Context only (no clear better direction)",IF(K34>=$F$3,"PRIORITY: Echuca well ahead",IF(K34>0,"Echuca ahead",IF(K34<=-$F$3,"United strength","United ahead or level")))) -> Echuca ahead
A35: MI50 | B35: Marks inside 50 | C35: Y | D35: =INDEX('League Per Game'!$Y$5:$Y$16,MATCH("Shepparton United",'League Per Game'!$A$5:$A$16,0)) -> 15.1 | E35: =INDEX('League Per Game'!$Y$5:$Y$16,MATCH("Echuca",'League Per Game'!$A$5:$A$16,0)) -> 15.9 | F35: =AVERAGE('League Per Game'!$Y$5:$Y$16) -> 11.85 | G35: =E35-D35 -> 0.8 | H35: =IF(D35=0,"",G35/D35) -> 0.052980132 | I35: =IF(C35="N",RANK(D35,'League Per Game'!$Y$5:$Y$16,1),RANK(D35,'League Per Game'!$Y$5:$Y$16,0)) -> 2 | J35: =IF(C35="N",RANK(E35,'League Per Game'!$Y$5:$Y$16,1),RANK(E35,'League Per Game'!$Y$5:$Y$16,0)) -> 1 | K35: =IF(OR(C35="?",STDEVP('League Per Game'!$Y$5:$Y$16)=0),"",IF(C35="N",-1,1)*G35/STDEVP('League Per Game'!$Y$5:$Y$16)) -> 0.31786685 | L35: =IF(K35="","Context only (no clear better direction)",IF(K35>=$F$3,"PRIORITY: Echuca well ahead",IF(K35>0,"Echuca ahead",IF(K35<=-$F$3,"United strength","United ahead or level")))) -> Echuca ahead
A36: BTO | B36: Back-half turnovers | C36: N | D36: =INDEX('League Per Game'!$AH$5:$AH$16,MATCH("Shepparton United",'League Per Game'!$A$5:$A$16,0)) -> 5 | E36: =INDEX('League Per Game'!$AH$5:$AH$16,MATCH("Echuca",'League Per Game'!$A$5:$A$16,0)) -> 4.7 | F36: =AVERAGE('League Per Game'!$AH$5:$AH$16) -> 5.575 | G36: =E36-D36 -> -0.3 | H36: =IF(D36=0,"",G36/D36) -> -0.06 | I36: =IF(C36="N",RANK(D36,'League Per Game'!$AH$5:$AH$16,1),RANK(D36,'League Per Game'!$AH$5:$AH$16,0)) -> 5 | J36: =IF(C36="N",RANK(E36,'League Per Game'!$AH$5:$AH$16,1),RANK(E36,'League Per Game'!$AH$5:$AH$16,0)) -> 4 | K36: =IF(OR(C36="?",STDEVP('League Per Game'!$AH$5:$AH$16)=0),"",IF(C36="N",-1,1)*G36/STDEVP('League Per Game'!$AH$5:$AH$16)) -> 0.25504989 | L36: =IF(K36="","Context only (no clear better direction)",IF(K36>=$F$3,"PRIORITY: Echuca well ahead",IF(K36>0,"Echuca ahead",IF(K36<=-$F$3,"United strength","United ahead or level")))) -> Echuca ahead
A37: DE% | B37: Disposal efficiency % | C37: Y | D37: =INDEX('League Per Game'!$AT$5:$AT$16,MATCH("Shepparton United",'League Per Game'!$A$5:$A$16,0)) -> 69 | E37: =INDEX('League Per Game'!$AT$5:$AT$16,MATCH("Echuca",'League Per Game'!$A$5:$A$16,0)) -> 69 | F37: =AVERAGE('League Per Game'!$AT$5:$AT$16) -> 67 | G37: =E37-D37 -> 0 | H37: =IF(D37=0,"",G37/D37) -> 0 | I37: =IF(C37="N",RANK(D37,'League Per Game'!$AT$5:$AT$16,1),RANK(D37,'League Per Game'!$AT$5:$AT$16,0)) -> 1 | J37: =IF(C37="N",RANK(E37,'League Per Game'!$AT$5:$AT$16,1),RANK(E37,'League Per Game'!$AT$5:$AT$16,0)) -> 1 | K37: =IF(OR(C37="?",STDEVP('League Per Game'!$AT$5:$AT$16)=0),"",IF(C37="N",-1,1)*G37/STDEVP('League Per Game'!$AT$5:$AT$16)) -> 0 | L37: =IF(K37="","Context only (no clear better direction)",IF(K37>=$F$3,"PRIORITY: Echuca well ahead",IF(K37>0,"Echuca ahead",IF(K37<=-$F$3,"United strength","United ahead or level")))) -> United ahead or level
A38: BUC | B38: Ball-up clearances | C38: Y | D38: =INDEX('League Per Game'!$AA$5:$AA$16,MATCH("Shepparton United",'League Per Game'!$A$5:$A$16,0)) -> 20.1 | E38: =INDEX('League Per Game'!$AA$5:$AA$16,MATCH("Echuca",'League Per Game'!$A$5:$A$16,0)) -> 20.1 | F38: =AVERAGE('League Per Game'!$AA$5:$AA$16) -> 19.466667 | G38: =E38-D38 -> 0 | H38: =IF(D38=0,"",G38/D38) -> 0 | I38: =IF(C38="N",RANK(D38,'League Per Game'!$AA$5:$AA$16,1),RANK(D38,'League Per Game'!$AA$5:$AA$16,0)) -> 5 | J38: =IF(C38="N",RANK(E38,'League Per Game'!$AA$5:$AA$16,1),RANK(E38,'League Per Game'!$AA$5:$AA$16,0)) -> 5 | K38: =IF(OR(C38="?",STDEVP('League Per Game'!$AA$5:$AA$16)=0),"",IF(C38="N",-1,1)*G38/STDEVP('League Per Game'!$AA$5:$AA$16)) -> 0 | L38: =IF(K38="","Context only (no clear better direction)",IF(K38>=$F$3,"PRIORITY: Echuca well ahead",IF(K38>0,"Echuca ahead",IF(K38<=-$F$3,"United strength","United ahead or level")))) -> United ahead or level
A39: FF | B39: Frees for | C39: Y | D39: =INDEX('League Per Game'!$AD$5:$AD$16,MATCH("Shepparton United",'League Per Game'!$A$5:$A$16,0)) -> 18.2 | E39: =INDEX('League Per Game'!$AD$5:$AD$16,MATCH("Echuca",'League Per Game'!$A$5:$A$16,0)) -> 17.1 | F39: =AVERAGE('League Per Game'!$AD$5:$AD$16) -> 18.966667 | G39: =E39-D39 -> -1.1 | H39: =IF(D39=0,"",G39/D39) -> -0.06043956 | I39: =IF(C39="N",RANK(D39,'League Per Game'!$AD$5:$AD$16,1),RANK(D39,'League Per Game'!$AD$5:$AD$16,0)) -> 8 | J39: =IF(C39="N",RANK(E39,'League Per Game'!$AD$5:$AD$16,1),RANK(E39,'League Per Game'!$AD$5:$AD$16,0)) -> 10 | K39: =IF(OR(C39="?",STDEVP('League Per Game'!$AD$5:$AD$16)=0),"",IF(C39="N",-1,1)*G39/STDEVP('League Per Game'!$AD$5:$AD$16)) -> -0.48367551 | L39: =IF(K39="","Context only (no clear better direction)",IF(K39>=$F$3,"PRIORITY: Echuca well ahead",IF(K39>0,"Echuca ahead",IF(K39<=-$F$3,"United strength","United ahead or level")))) -> United ahead or level
A40: R50% | B40: Rebound-50 efficiency % | C40: Y | D40: =INDEX('League Per Game'!$AY$5:$AY$16,MATCH("Shepparton United",'League Per Game'!$A$5:$A$16,0)) -> 64 | E40: =INDEX('League Per Game'!$AY$5:$AY$16,MATCH("Echuca",'League Per Game'!$A$5:$A$16,0)) -> 63 | F40: =AVERAGE('League Per Game'!$AY$5:$AY$16) -> 61.25 | G40: =E40-D40 -> -1 | H40: =IF(D40=0,"",G40/D40) -> -0.015625 | I40: =IF(C40="N",RANK(D40,'League Per Game'!$AY$5:$AY$16,1),RANK(D40,'League Per Game'!$AY$5:$AY$16,0)) -> 1 | J40: =IF(C40="N",RANK(E40,'League Per Game'!$AY$5:$AY$16,1),RANK(E40,'League Per Game'!$AY$5:$AY$16,0)) -> 3 | K40: =IF(OR(C40="?",STDEVP('League Per Game'!$AY$5:$AY$16)=0),"",IF(C40="N",-1,1)*G40/STDEVP('League Per Game'!$AY$5:$AY$16)) -> -0.53293871 | L40: =IF(K40="","Context only (no clear better direction)",IF(K40>=$F$3,"PRIORITY: Echuca well ahead",IF(K40>0,"Echuca ahead",IF(K40<=-$F$3,"United strength","United ahead or level")))) -> United ahead or level
A41: IM | B41: Intercept marks | C41: Y | D41: =INDEX('League Per Game'!$X$5:$X$16,MATCH("Shepparton United",'League Per Game'!$A$5:$A$16,0)) -> 16.8 | E41: =INDEX('League Per Game'!$X$5:$X$16,MATCH("Echuca",'League Per Game'!$A$5:$A$16,0)) -> 16 | F41: =AVERAGE('League Per Game'!$X$5:$X$16) -> 15.375 | G41: =E41-D41 -> -0.8 | H41: =IF(D41=0,"",G41/D41) -> -0.047619048 | I41: =IF(C41="N",RANK(D41,'League Per Game'!$X$5:$X$16,1),RANK(D41,'League Per Game'!$X$5:$X$16,0)) -> 3 | J41: =IF(C41="N",RANK(E41,'League Per Game'!$X$5:$X$16,1),RANK(E41,'League Per Game'!$X$5:$X$16,0)) -> 5 | K41: =IF(OR(C41="?",STDEVP('League Per Game'!$X$5:$X$16)=0),"",IF(C41="N",-1,1)*G41/STDEVP('League Per Game'!$X$5:$X$16)) -> -0.58866909 | L41: =IF(K41="","Context only (no clear better direction)",IF(K41>=$F$3,"PRIORITY: Echuca well ahead",IF(K41>0,"Echuca ahead",IF(K41<=-$F$3,"United strength","United ahead or level")))) -> United ahead or level
...

Sheet League Per Game
A1: All 12 GVL clubs: per-game averages, 2026 season (including finals)
A2: Source: Premier Data Leaderboards > Teams > Averages. Percent columns are whole-number percentages (69 = 69%). Hover a header for its full name.
A4: Team | B4: Games | C4: RP | D4: D | E4: K | F4: HB | G4: CP | H4: M | I4: Cl | J4: I50 | K4: G | L4: B | M4: SI | N4: IP | O4: T | P4: HO | Q4: HOA | R4: TGB | S4: HBG | T4: LBG | U4: HR | V4: CM | W4: UM | X4: IM | Y4: MI50 | Z4: CC | AA4: BUC | AB4: TIC | AC4: R50 | AD4: FF | AE4: KI | AF4: 1% | AG4: GST | AH4: BTO | AI4: MTO | AJ4: FTO | AK4: PR | AL4: Ch | AM4: Sm | AN4: Sp | AO4: FTKL | AP4: MTKL | AQ4: BTKL | AR4: GA | AS4: GA% | AT4: DE% | AU4: K% | AV4: H% | AW4: I50% | AX4: C% | AY4: R50%
A5: Echuca | B5: 21 | C5: 1739.5 | D5: 372.4 | E5: 229.9 | F5: 142.5 | G5: 152.9 | H5: 99.3 | I5: 43.6 | J5: 55.6 | K5: 14.8 | L5: 11.7 | M5: 100.1 | N5: 74.2 | O5: 66 | P5: 42.3 | Q5: 9.2 | R5: 100.2 | S5: 34.1 | T5: 66 | U5: 8.3 | V5: 15.4 | W5: 84 | X5: 16 | Y5: 15.9 | Z5: 10.8 | AA5: 20.1 | AB5: 12.8 | AC5: 33.2 | AD5: 17.1 | AE5: 9 | AF5: 45.4 | AG5: 9.5 | AH5: 4.7 | AI5: 43.2 | AJ5: 27.4 | AK5: 129.4 | AL5: 10.8 | AM5: 6 | AN5: 19.4 | AO5: 11.5 | AP5: 42.9 | AQ5: 11.6 | AR5: 13.1 | AS5: 53 | AT5: 69 | AU5: 62 | AV5: 79 | AW5: 54 | AX5: 64 | AY5: 63
A6: Kyabram | B6: 21 | C6: 1732.4 | D6: 373.2 | E6: 231.1 | F6: 142.1 | G6: 149.5 | H6: 102.5 | I6: 47.2 | J6: 52.6 | K6: 13.2 | L6: 10.5 | M6: 93.2 | N6: 72.4 | O6: 61.7 | P6: 52.8 | Q6: 11.8 | R6: 93.9 | S6: 34.1 | T6: 59.8 | U6: 9 | V6: 16.2 | W6: 86.3 | X6: 17.1 | Y6: 13.1 | Z6: 12 | AA6: 21.7 | AB6: 13.4 | AC6: 34.9 | AD6: 15.8 | AE6: 9.4 | AF6: 42.9 | AG6: 8.4 | AH6: 4.2 | AI6: 42.7 | AJ6: 26.5 | AK6: 122.1 | AL6: 12.7 | AM6: 4.3 | AN6: 16.1 | AO6: 14.1 | AP6: 38.2 | AQ6: 9.4 | AR6: 11.3 | AS6: 51 | AT6: 68 | AU6: 61 | AV6: 79 | AW6: 51 | AX6: 61 | AY6: 63
A7: Shepparton Bears | B7: 22 | C7: 1713.4 | D7: 356.2 | E7: 221 | F7: 135.2 | G7: 143.5 | H7: 95.1 | I7: 45.5 | J7: 54.7 | K7: 13.6 | L7: 9.9 | M7: 90 | N7: 77.1 | O7: 66.9 | P7: 65.2 | Q7: 16.9 | R7: 90.6 | S7: 32.4 | T7: 58.2 | U7: 7.9 | V7: 14 | W7: 81 | X7: 16.5 | Y7: 13.7 | Z7: 11 | AA7: 21.3 | AB7: 13.2 | AC7: 32.7 | AD7: 18.7 | AE7: 8.4 | AF7: 48.9 | AG7: 8.8 | AH7: 4.6 | AI7: 43.1 | AJ7: 29 | AK7: 133.2 | AL7: 11.4 | AM7: 5.2 | AN7: 22 | AO7: 13.9 | AP7: 41.7 | AQ7: 11.3 | AR7: 11.8 | AS7: 52 | AT7: 66 | AU7: 60 | AV7: 76 | AW7: 48 | AX7: 61 | AY7: 60
A8: Shepparton United | B8: 18 | C8: 1617.7 | D8: 349.7 | E8: 224.3 | F8: 125.4 | G8: 128.9 | H8: 110.4 | I8: 41.8 | J8: 48.3 | K8: 11.6 | L8: 9.1 | M8: 84.4 | N8: 68.3 | O8: 55.2 | P8: 56.2 | Q8: 11.8 | R8: 77.9 | S8: 28.4 | T8: 49.6 | U8: 7.4 | V8: 14.3 | W8: 96.1 | X8: 16.8 | Y8: 15.1 | Z8: 10 | AA8: 20.1 | AB8: 11.7 | AC8: 30.8 | AD8: 18.2 | AE8: 9.2 | AF8: 36.3 | AG8: 7.1 | AH8: 5 | AI8: 39 | AJ8: 24.6 | AK8: 105.2 | AL8: 12.7 | AM8: 3.2 | AN8: 13.7 | AO8: 10.2 | AP8: 34.3 | AQ8: 10.6 | AR8: 9.7 | AS8: 50 | AT8: 69 | AU8: 64 | AV8: 77 | AW8: 51 | AX8: 61 | AY8: 64
A9: Seymour | B9: 18 | C9: 1567.3 | D9: 323.4 | E9: 208.4 | F9: 114.9 | G9: 138.2 | H9: 95.3 | I9: 43.3 | J9: 48.6 | K9: 11.8 | L9: 9.4 | M9: 85.4 | N9: 69.9 | O9: 60.2 | P9: 54 | Q9: 11 | R9: 83.9 | S9: 32.5 | T9: 51.4 | U9: 8.9 | V9: 15 | W9: 80.3 | X9: 15.8 | Y9: 13.8 | Z9: 10.8 | AA9: 19.9 | AB9: 12.6 | AC9: 33.3 | AD9: 19.6 | AE9: 9.4 | AF9: 43.2 | AG9: 7.4 | AH9: 6.1 | AI9: 41.9 | AJ9: 23.9 | AK9: 127.2 | AL9: 13.1 | AM9: 4.4 | AN9: 17.1 | AO9: 11.5 | AP9: 36.9 | AQ9: 11.8 | AR9: 9.9 | AS9: 48 | AT9: 67 | AU9: 61 | AV9: 78 | AW9: 50 | AX9: 59 | AY9: 60
A10: Rochester | B10: 18 | C10: 1565.3 | D10: 339.1 | E10: 204.2 | F10: 134.9 | G10: 143.7 | H10: 83.4 | I10: 44.2 | J10: 54 | K10: 11.4 | L10: 9.7 | M10: 77.2 | N10: 74 | O10: 65.8 | P10: 41.4 | Q10: 8.8 | R10: 96.3 | S10: 37.6 | T10: 58.8 | U10: 10.3 | V10: 13 | W10: 70.4 | X10: 15.6 | Y10: 11.6 | Z10: 10.9 | AA10: 21.2 | AB10: 12.1 | AC10: 34.7 | AD10: 17.2 | AE10: 11.3 | AF10: 44.2 | AG10: 6.7 | AH10: 5.1 | AI10: 45.4 | AJ10: 30.7 | AK10: 128.3 | AL10: 10.9 | AM10: 3.8 | AN10: 21.1 | AO10: 12.6 | AP10: 39.2 | AQ10: 14.1 | AR10: 9.6 | AS10: 49 | AT10: 66 | AU10: 59 | AV10: 77 | AW10: 49 | AX10: 65 | AY10: 62
A11: Mooroopna | B11: 20 | C11: 1552 | D11: 338.6 | E11: 199.1 | F11: 139.6 | G11: 135.2 | H11: 81.3 | I11: 44.5 | J11: 44.4 | K11: 10.6 | L11: 8.8 | M11: 71.3 | N11: 68 | O11: 65.2 | P11: 52.6 | Q11: 11.2 | R11: 81 | S11: 29.1 | T11: 51.9 | U11: 10.1 | V11: 12.4 | W11: 68.8 | X11: 14.1 | Y11: 10.3 | Z11: 8.5 | AA11: 22.3 | AB11: 13.7 | AC11: 38 | AD11: 19.7 | AE11: 11.3 | AF11: 41.6 | AG11: 6.2 | AH11: 5.2 | AI11: 43.7 | AJ11: 21.4 | AK11: 129.8 | AL11: 13.6 | AM11: 4.3 | AN11: 17.1 | AO11: 10.6 | AP11: 39.8 | AQ11: 14.8 | AR11: 8.3 | AS11: 50 | AT11: 67 | AU11: 59 | AV11: 79 | AW11: 51 | AX11: 64 | AY11: 59
A12: Mansfield | B12: 18 | C12: 1533.1 | D12: 323.2 | E12: 193.6 | F12: 129.6 | G12: 139.9 | H12: 74.1 | I12: 43.7 | J12: 51.2 | K12: 12.5 | L12: 10.4 | M12: 80.9 | N12: 72.5 | O12: 70.8 | P12: 43 | Q12: 10.8 | R12: 91.6 | S12: 27.7 | T12: 63.9 | U12: 8.3 | V12: 12.3 | W12: 61.7 | X12: 13.8 | Y12: 11.4 | Z12: 11.7 | AA12: 19.4 | AB12: 12.7 | AC12: 33.1 | AD12: 24.6 | AE12: 11.4 | AF12: 45.8 | AG12: 7.2 | AH12: 6.2 | AI12: 42.6 | AJ12: 27.5 | AK12: 135.1 | AL12: 9.5 | AM12: 5.9 | AN12: 17.8 | AO12: 13.4 | AP12: 42.2 | AQ12: 15.2 | AR12: 10.4 | AS12: 50 | AT12: 65 | AU12: 56 | AV12: 78 | AW12: 46 | AX12: 62 | AY12: 59
A13: Shepparton Swans | B13: 19 | C13: 1514.5 | D13: 324.7 | E13: 206.9 | F13: 117.8 | G13: 126.8 | H13: 88.5 | I13: 39.4 | J13: 46.3 | K13: 10.5 | L13: 9.1 | M13: 71.8 | N13: 70.4 | O13: 67.8 | P13: 34.9 | Q13: 6.4 | R13: 86.4 | S13: 29.8 | T13: 56.6 | U13: 9.4 | V13: 9.8 | W13: 78.6 | X13: 13.4 | Y13: 11.8 | Z13: 8.7 | AA13: 18.8 | AB13: 11.9 | AC13: 35.7 | AD13: 20.2 | AE13: 10.7 | AF13: 46 | AG13: 6.5 | AH13: 4.2 | AI13: 43.4 | AJ13: 23.4 | AK13: 135.4 | AL13: 14 | AM13: 3.8 | AN13: 16.4 | AO13: 11.7 | AP13: 43.1 | AQ13: 13.1 | AR13: 8.8 | AS13: 50 | AT13: 66 | AU13: 60 | AV13: 78 | AW13: 51 | AX13: 62 | AY13: 62
A14: Euroa | B14: 17 | C14: 1479.1 | D14: 330.8 | E14: 194.3 | F14: 136.5 | G14: 128.1 | H14: 86.4 | I14: 36.5 | J14: 37.4 | K14: 8.1 | L14: 6.4 | M14: 61.6 | N14: 65.3 | O14: 61.9 | P14: 33.4 | Q14: 9 | R14: 84.4 | S14: 30.6 | T14: 53.8 | U14: 10.1 | V14: 11.9 | W14: 74.5 | X14: 14.2 | Y14: 9.5 | Z14: 9.1 | AA14: 15.1 | AB14: 12.4 | AC14: 39.7 | AD14: 19.9 | AE14: 11.9 | AF14: 39.7 | AG14: 5.4 | AH14: 6.2 | AI14: 44.9 | AJ14: 20.5 | AK14: 122.1 | AL14: 12 | AM14: 3.9 | AN14: 15.7 | AO14: 9.6 | AP14: 34.8 | AQ14: 17.5 | AR14: 7.1 | AS14: 49 | AT14: 69 | AU14: 62 | AV14: 79 | AW14: 51 | AX14: 66 | AY14: 64
A15: Benalla | B15: 17 | C15: 1428.7 | D15: 318.1 | E15: 196.6 | F15: 121.5 | G15: 128.9 | H15: 85.9 | I15: 39.3 | J15: 39.9 | K15: 8.1 | L15: 6.5 | M15: 56.9 | N15: 66.3 | O15: 51.1 | P15: 56.6 | Q15: 13.6 | R15: 79.8 | S15: 28.3 | T15: 51.5 | U15: 7.4 | V15: 13.1 | W15: 72.8 | X15: 13.9 | Y15: 9.1 | Z15: 9.4 | AA15: 17.3 | AB15: 12.6 | AC15: 39.8 | AD15: 20.4 | AE15: 13.5 | AF15: 45.4 | AG15: 5.6 | AH15: 7.3 | AI15: 44.8 | AJ15: 23.1 | AK15: 111.6 | AL15: 12.2 | AM15: 3.7 | AN15: 20.2 | AO15: 7.3 | AP15: 33.1 | AQ15: 10.7 | AR15: 6.6 | AS15: 48 | AT15: 65 | AU15: 59 | AV15: 74 | AW15: 48 | AX15: 58 | AY15: 60
A16: Tatura | B16: 17 | C16: 1425.4 | D16: 323.2 | E16: 206.4 | F16: 116.9 | G16: 123.1 | H16: 99.6 | I16: 38.8 | J16: 31.1 | K16: 5.5 | L16: 4.3 | M16: 38.6 | N16: 63.4 | O16: 51.8 | P16: 50.6 | Q16: 13.5 | R16: 77 | S16: 25.2 | T16: 51.8 | U16: 6.9 | V16: 12 | W16: 87.6 | X16: 17.3 | Y16: 6.9 | Z16: 9.9 | AA16: 16.4 | AB16: 12.5 | AC16: 43 | AD16: 16.2 | AE16: 14.8 | AF16: 40.3 | AG16: 2.8 | AH16: 8.1 | AI16: 49.6 | AJ16: 17.8 | AK16: 111.2 | AL16: 15.1 | AM16: 3.2 | AN16: 15.7 | AO16: 6.4 | AP16: 32.1 | AQ16: 13.3 | AR16: 4.5 | AS16: 46 | AT16: 67 | AU16: 60 | AV16: 78 | AW16: 43 | AX16: 56 | AY16: 59

Sheet League Season Totals
A1: All 12 GVL clubs: season totals, 2026 (including finals)
A2: Source: Premier Data Leaderboards > Teams > Totals. Finals teams played more games, so compare per-game averages for fairness.
A4: Team | B4: Games | C4: RP | D4: D | E4: K | F4: HB | G4: CP | H4: M | I4: Cl | J4: I50 | K4: G | L4: B | M4: SI | N4: IP | O4: T | P4: HO | Q4: HOA | R4: TGB | S4: HBG | T4: LBG | U4: HR | V4: CM | W4: UM | X4: IM | Y4: MI50 | Z4: CC | AA4: BUC | AB4: TIC | AC4: R50 | AD4: FF | AE4: KI | AF4: 1% | AG4: GST | AH4: BTO | AI4: MTO | AJ4: FTO | AK4: PR | AL4: Ch | AM4: Sm | AN4: Sp | AO4: FTKL | AP4: MTKL | AQ4: BTKL | AR4: GA | AS4: GA% | AT4: DE% | AU4: K% | AV4: H% | AW4: I50% | AX4: C% | AY4: R50%
A5: Shepparton Bears | B5: 22 | C5: 37695 | D5: 7836 | E5: 4862 | F5: 2974 | G5: 3157 | H5: 2092 | I5: 1000 | J5: 1203 | K5: 300 | L5: 217 | M5: 1979 | N5: 1697 | O5: 1471 | P5: 1435 | Q5: 371 | R5: 1994 | S5: 713 | T5: 1281 | U5: 174 | V5: 309 | W5: 1783 | X5: 363 | Y5: 301 | Z5: 242 | AA5: 468 | AB5: 290 | AC5: 720 | AD5: 412 | AE5: 185 | AF5: 1075 | AG5: 194 | AH5: 101 | AI5: 949 | AJ5: 639 | AK5: 2931 | AL5: 251 | AM5: 114 | AN5: 484 | AO5: 305 | AP5: 917 | AQ5: 249 | AR5: 259 | AS5: 52 | AT5: 66 | AU5: 60 | AV5: 76 | AW5: 48 | AX5: 61 | AY5: 60
A6: Echuca | B6: 21 | C6: 36530 | D6: 7821 | E6: 4828 | F6: 2993 | G6: 3211 | H6: 2086 | I6: 916 | J6: 1167 | K6: 310 | L6: 245 | M6: 2102 | N6: 1559 | O6: 1387 | P6: 888 | Q6: 193 | R6: 2104 | S6: 717 | T6: 1387 | U6: 174 | V6: 323 | W6: 1763 | X6: 336 | Y6: 333 | Z6: 226 | AA6: 422 | AB6: 268 | AC6: 698 | AD6: 359 | AE6: 189 | AF6: 953 | AG6: 199 | AH6: 98 | AI6: 908 | AJ6: 576 | AK6: 2717 | AL6: 226 | AM6: 126 | AN6: 408 | AO6: 242 | AP6: 901 | AQ6: 244 | AR6: 275 | AS6: 53 | AT6: 69 | AU6: 62 | AV6: 79 | AW6: 54 | AX6: 64 | AY6: 63
A7: Kyabram | B7: 21 | C7: 36381 | D7: 7837 | E7: 4853 | F7: 2984 | G7: 3140 | H7: 2153 | I7: 991 | J7: 1105 | K7: 277 | L7: 220 | M7: 1957 | N7: 1520 | O7: 1296 | P7: 1109 | Q7: 247 | R7: 1972 | S7: 716 | T7: 1256 | U7: 189 | V7: 340 | W7: 1813 | X7: 359 | Y7: 275 | Z7: 253 | AA7: 456 | AB7: 282 | AC7: 733 | AD7: 332 | AE7: 197 | AF7: 900 | AG7: 177 | AH7: 88 | AI7: 897 | AJ7: 556 | AK7: 2565 | AL7: 267 | AM7: 91 | AN7: 338 | AO7: 296 | AP7: 802 | AQ7: 198 | AR7: 237 | AS7: 51 | AT7: 68 | AU7: 61 | AV7: 79 | AW7: 51 | AX7: 61 | AY7: 63
A8: Mooroopna | B8: 20 | C8: 31039 | D8: 6773 | E8: 3981 | F8: 2792 | G8: 2705 | H8: 1626 | I8: 890 | J8: 888 | K8: 212 | L8: 175 | M8: 1426 | N8: 1359 | O8: 1305 | P8: 1052 | Q8: 225 | R8: 1619 | S8: 581 | T8: 1038 | U8: 202 | V8: 249 | W8: 1377 | X8: 282 | Y8: 207 | Z8: 170 | AA8: 446 | AB8: 274 | AC8: 760 | AD8: 394 | AE8: 226 | AF8: 832 | AG8: 125 | AH8: 103 | AI8: 874 | AJ8: 427 | AK8: 2595 | AL8: 271 | AM8: 86 | AN8: 343 | AO8: 212 | AP8: 796 | AQ8: 297 | AR8: 166 | AS8: 50 | AT8: 67 | AU8: 59 | AV8: 79 | AW8: 51 | AX8: 64 | AY8: 59
A9: Shepparton United | B9: 18 | C9: 29119 | D9: 6295 | E9: 4038 | F9: 2257 | G9: 2321 | H9: 1988 | I9: 752 | J9: 870 | K9: 208 | L9: 163 | M9: 1520 | N9: 1230 | O9: 993 | P9: 1012 | Q9: 212 | R9: 1403 | S9: 511 | T9: 892 | U9: 133 | V9: 258 | W9: 1730 | X9: 303 | Y9: 272 | Z9: 180 | AA9: 361 | AB9: 211 | AC9: 554 | AD9: 328 | AE9: 165 | AF9: 654 | AG9: 127 | AH9: 90 | AI9: 702 | AJ9: 443 | AK9: 1893 | AL9: 228 | AM9: 58 | AN9: 247 | AO9: 184 | AP9: 618 | AQ9: 191 | AR9: 175 | AS9: 50 | AT9: 69 | AU9: 64 | AV9: 77 | AW9: 51 | AX9: 61 | AY9: 64
A10: Shepparton Swans | B10: 19 | C10: 28775 | D10: 6170 | E10: 3932 | F10: 2238 | G10: 2410 | H10: 1681 | I10: 748 | J10: 879 | K10: 200 | L10: 173 | M10: 1365 | N10: 1338 | O10: 1288 | P10: 663 | Q10: 122 | R10: 1642 | S10: 566 | T10: 1076 | U10: 178 | V10: 187 | W10: 1494 | X10: 255 | Y10: 225 | Z10: 165 | AA10: 357 | AB10: 226 | AC10: 678 | AD10: 384 | AE10: 204 | AF10: 874 | AG10: 124 | AH10: 79 | AI10: 825 | AJ10: 445 | AK10: 2572 | AL10: 266 | AM10: 73 | AN10: 312 | AO10: 222 | AP10: 818 | AQ10: 248 | AR10: 167 | AS10: 50 | AT10: 66 | AU10: 60 | AV10: 78 | AW10: 51 | AX10: 62 | AY10: 62
A11: Seymour | B11: 18 | C11: 28212 | D11: 5821 | E11: 3752 | F11: 2069 | G11: 2488 | H11: 1715 | I11: 780 | J11: 874 | K11: 213 | L11: 170 | M11: 1538 | N11: 1259 | O11: 1084 | P11: 972 | Q11: 198 | R11: 1511 | S11: 585 | T11: 926 | U11: 160 | V11: 270 | W11: 1445 | X11: 285 | Y11: 248 | Z11: 195 | AA11: 358 | AB11: 227 | AC11: 599 | AD11: 353 | AE11: 169 | AF11: 778 | AG11: 134 | AH11: 110 | AI11: 755 | AJ11: 430 | AK11: 2290 | AL11: 236 | AM11: 80 | AN11: 307 | AO11: 207 | AP11: 664 | AQ11: 213 | AR11: 179 | AS11: 48 | AT11: 67 | AU11: 61 | AV11: 78 | AW11: 50 | AX11: 59 | AY11: 60
A12: Rochester | B12: 18 | C12: 28175 | D12: 6104 | E12: 3675 | F12: 2429 | G12: 2586 | H12: 1501 | I12: 795 | J12: 972 | K12: 206 | L12: 174 | M12: 1390 | N12: 1332 | O12: 1185 | P12: 745 | Q12: 158 | R12: 1734 | S12: 676 | T12: 1058 | U12: 186 | V12: 234 | W12: 1267 | X12: 281 | Y12: 208 | Z12: 196 | AA12: 381 | AB12: 218 | AC12: 625 | AD12: 310 | AE12: 203 | AF12: 795 | AG12: 120 | AH12: 92 | AI12: 817 | AJ12: 553 | AK12: 2309 | AL12: 196 | AM12: 68 | AN12: 379 | AO12: 226 | AP12: 705 | AQ12: 254 | AR12: 172 | AS12: 49 | AT12: 66 | AU12: 59 | AV12: 77 | AW12: 49 | AX12: 65 | AY12: 62
A13: Mansfield | B13: 18 | C13: 27596 | D13: 5817 | E13: 3484 | F13: 2333 | G13: 2518 | H13: 1333 | I13: 787 | J13: 922 | K13: 225 | L13: 188 | M13: 1457 | N13: 1305 | O13: 1275 | P13: 774 | Q13: 194 | R13: 1649 | S13: 499 | T13: 1150 | U13: 150 | V13: 222 | W13: 1111 | X13: 248 | Y13: 206 | Z13: 210 | AA13: 349 | AB13: 228 | AC13: 596 | AD13: 443 | AE13: 205 | AF13: 824 | AG13: 130 | AH13: 111 | AI13: 767 | AJ13: 495 | AK13: 2432 | AL13: 171 | AM13: 106 | AN13: 320 | AO13: 241 | AP13: 760 | AQ13: 274 | AR13: 188 | AS13: 50 | AT13: 65 | AU13: 56 | AV13: 78 | AW13: 46 | AX13: 62 | AY13: 59
A14: Euroa | B14: 17 | C14: 25144 | D14: 5623 | E14: 3303 | F14: 2320 | G14: 2178 | H14: 1468 | I14: 621 | J14: 636 | K14: 138 | L14: 109 | M14: 1048 | N14: 1110 | O14: 1052 | P14: 567 | Q14: 153 | R14: 1435 | S14: 520 | T14: 915 | U14: 172 | V14: 202 | W14: 1266 | X14: 241 | Y14: 162 | Z14: 154 | AA14: 256 | AB14: 211 | AC14: 675 | AD14: 339 | AE14: 203 | AF14: 675 | AG14: 91 | AH14: 106 | AI14: 764 | AJ14: 349 | AK14: 2076 | AL14: 204 | AM14: 66 | AN14: 267 | AO14: 163 | AP14: 591 | AQ14: 298 | AR14: 120 | AS14: 49 | AT14: 69 | AU14: 62 | AV14: 79 | AW14: 51 | AX14: 66 | AY14: 64
A15: Benalla | B15: 17 | C15: 24288 | D15: 5407 | E15: 3342 | F15: 2065 | G15: 2191 | H15: 1461 | I15: 668 | J15: 678 | K15: 137 | L15: 111 | M15: 967 | N15: 1127 | O15: 869 | P15: 963 | Q15: 231 | R15: 1357 | S15: 481 | T15: 876 | U15: 125 | V15: 223 | W15: 1238 | X15: 236 | Y15: 155 | Z15: 159 | AA15: 294 | AB15: 215 | AC15: 677 | AD15: 347 | AE15: 229 | AF15: 772 | AG15: 95 | AH15: 124 | AI15: 762 | AJ15: 392 | AK15: 1898 | AL15: 208 | AM15: 63 | AN15: 344 | AO15: 124 | AP15: 563 | AQ15: 182 | AR15: 113 | AS15: 48 | AT15: 65 | AU15: 59 | AV15: 74 | AW15: 48 | AX15: 58 | AY15: 60
A16: Tatura | B16: 17 | C16: 24231 | D16: 5495 | E16: 3508 | F16: 1987 | G16: 2093 | H16: 1694 | I16: 660 | J16: 529 | K16: 93 | L16: 73 | M16: 656 | N16: 1078 | O16: 880 | P16: 860 | Q16: 229 | R16: 1309 | S16: 428 | T16: 881 | U16: 118 | V16: 204 | W16: 1490 | X16: 294 | Y16: 118 | Z16: 168 | AA16: 279 | AB16: 213 | AC16: 731 | AD16: 276 | AE16: 252 | AF16: 685 | AG16: 48 | AH16: 137 | AI16: 844 | AJ16: 302 | AK16: 1890 | AL16: 256 | AM16: 54 | AN16: 267 | AO16: 109 | AP16: 545 | AQ16: 226 | AR16: 77 | AS16: 46 | AT16: 67 | AU16: 60 | AV16: 78 | AW16: 43 | AX16: 56 | AY16: 59

Sheet United Games For
A1: Shepparton United 2026: Shepparton United's own stats in each game
A2: Source: Premier Data Team Summary > Match Statistics. Hover a header for its full name.
A4: Opponent | B4: Round | C4: Stage | D4: Result | E4: D | F4: K | G4: HB | H4: CP | I4: TGB | J4: HBG | K4: LBG | L4: IP | M4: GTH | N4: HR | O4: M | P4: CM | Q4: UM | R4: IM | S4: MI50 | T4: RP | U4: HO | V4: HOA | W4: Cl | X4: CC | Y4: BUC | Z4: TIC | AA4: I50 | AB4: R50 | AC4: FF | AD4: KI | AE4: 1% | AF4: TO | AG4: BTO | AH4: MTO | AI4: FTO | AJ4: PR | AK4: PRA | AL4: Ch | AM4: Sm | AN4: Sp | AO4: PRF | AP4: T | AQ4: TE | AR4: FTKL | AS4: MTKL | AT4: BTKL | AU4: G | AV4: B | AW4: RB | AX4: SE% | AY4: SS | AZ4: GA% | BA4: DE% | BB4: I50% | BC4: K% | BD4: H% | BE4: C% | BF4: R50% | BG4: KI% | BH4: KE | BI4: HE | BJ4: ED | BK4: EFFC | BL4: EFFR
A5: Shepparton Bears | B5: 1 | C5: Home & away | D5: L | E5: 298 | F5: 184 | G5: 114 | H5: 122 | I5: 63 | J5: 19 | K5: 44 | L5: 67 | M5: 67 | N5: 7 | O5: 77 | P5: 12 | Q5: 65 | R5: 15 | S5: 8 | T5: 1191 | U5: 57 | V5: 9 | W5: 45 | X5: 8 | Y5: 20 | Z5: 17 | AA5: 37 | AB5: 29 | AC5: 16 | AD5: 8 | AE5: 28 | AF5: 82 | AG5: 7 | AH5: 48 | AI5: 27 | AJ5: 79 | AK5: 17 | AL5: 14 | AM5: 2 | AN5: 10 | AO5: 4 | AP5: 46 | AQ5: 37 | AR5: 4 | AS5: 34 | AT5: 8 | AU5: 5 | AV5: 4 | AW5: 0 | AX5: 24 | AY5: 9 | AZ5: 55 | BA5: 60 | BB5: 35 | BC5: 52 | BD5: 74 | BE5: 56 | BF5: 62 | BG5: 75 | BH5: 95 | BI5: 85 | BJ5: 180 | BK5: 25 | BL5: 18
A6: Euroa | B6: 2 | C6: Home & away | D6: W | E6: 271 | F6: 182 | G6: 89 | H6: 113 | I6: 53 | J6: 15 | K6: 38 | L6: 50 | M6: 43 | N6: 5 | O6: 86 | P6: 19 | Q6: 67 | R6: 12 | S6: 15 | T6: 1284 | U6: 49 | V6: 10 | W6: 36 | X6: 10 | Y6: 20 | Z6: 6 | AA6: 42 | AB6: 20 | AC6: 16 | AD6: 7 | AE6: 19 | AF6: 56 | AG6: 3 | AH6: 34 | AI6: 19 | AJ6: 81 | AK6: 27 | AL6: 9 | AM6: 3 | AN6: 6 | AO6: 6 | AP6: 42 | AQ6: 36 | AR6: 11 | AS6: 24 | AT6: 7 | AU6: 11 | AV6: 8 | AW6: 3 | AX6: 52 | AY6: 22 | AZ6: 50 | BA6: 70 | BB6: 69 | BC6: 65 | BD6: 79 | BE6: 64 | BF6: 80 | BG6: 100 | BH6: 119 | BI6: 71 | BJ6: 190 | BK6: 23 | BL6: 16
A7: Shepparton Swans | B7: 3 | C7: Home & away | D7: W | E7: 344 | F7: 230 | G7: 114 | H7: 158 | I7: 91 | J7: 34 | K7: 57 | L7: 69 | M7: 58 | N7: 2 | O7: 108 | P7: 14 | Q7: 94 | R7: 21 | S7: 11 | T7: 1698 | U7: 77 | V7: 18 | W7: 53 | X7: 7 | Y7: 27 | Z7: 19 | AA7: 53 | AB7: 44 | AC7: 16 | AD7: 12 | AE7: 40 | AF7: 80 | AG7: 4 | AH7: 48 | AI7: 28 | AJ7: 131 | AK7: 63 | AL7: 15 | AM7: 0 | AN7: 15 | AO7: 12 | AP7: 53 | AQ7: 49 | AR7: 19 | AS7: 27 | AT7: 7 | AU7: 8 | AV7: 10 | AW7: 1 | AX7: 35 | AY7: 19 | AZ7: 42 | BA7: 67 | BB7: 53 | BC7: 66 | BD7: 68 | BE7: 57 | BF7: 75 | BG7: 92 | BH7: 152 | BI7: 78 | BJ7: 230 | BK7: 30 | BL7: 33
A8: Mooroopna | B8: 4 | C8: Home & away | D8: L | E8: 333 | F8: 200 | G8: 133 | H8: 132 | I8: 88 | J8: 27 | K8: 61 | L8: 79 | M8: 46 | N8: 8 | O8: 86 | P8: 14 | Q8: 72 | R8: 12 | S8: 12 | T8: 1430 | U8: 55 | V8: 6 | W8: 34 | X8: 7 | Y8: 17 | Z8: 10 | AA8: 49 | AB8: 27 | AC8: 23 | AD8: 5 | AE8: 33 | AF8: 70 | AG8: 5 | AH8: 34 | AI8: 31 | AJ8: 99 | AK8: 20 | AL8: 15 | AM8: 9 | AN8: 6 | AO8: 0 | AP8: 55 | AQ8: 50 | AR8: 8 | AS8: 40 | AT8: 7 | AU8: 8 | AV8: 7 | AW8: 3 | AX8: 36 | AY8: 18 | AZ8: 44 | BA8: 65 | BB8: 35 | BC8: 57 | BD8: 75 | BE8: 59 | BF8: 59 | BG8: 80 | BH8: 115 | BI8: 100 | BJ8: 215 | BK8: 20 | BL8: 16
A9: Mansfield | B9: 5 | C9: Home & away | D9: L | E9: 353 | F9: 240 | G9: 113 | H9: 114 | I9: 73 | J9: 24 | K9: 49 | L9: 62 | M9: 42 | N9: 11 | O9: 138 | P9: 16 | Q9: 122 | R9: 17 | S9: 15 | T9: 1516 | U9: 45 | V9: 4 | W9: 35 | X9: 13 | Y9: 11 | Z9: 11 | AA9: 42 | AB9: 33 | AC9: 18 | AD9: 14 | AE9: 27 | AF9: 71 | AG9: 4 | AH9: 48 | AI9: 19 | AJ9: 69 | AK9: 23 | AL9: 10 | AM9: 5 | AN9: 11 | AO9: 4 | AP9: 31 | AQ9: 28 | AR9: 3 | AS9: 22 | AT9: 6 | AU9: 11 | AV9: 11 | AW9: 2 | AX9: 57 | AY9: 24 | AZ9: 45 | BA9: 71 | BB9: 62 | BC9: 68 | BD9: 77 | BE9: 60 | BF9: 64 | BG9: 93 | BH9: 163 | BI9: 88 | BJ9: 251 | BK9: 21 | BL9: 21
A10: Echuca | B10: 6 | C10: Home & away | D10: L | E10: 344 | F10: 234 | G10: 110 | H10: 133 | I10: 79 | J10: 29 | K10: 50 | L10: 65 | M10: 36 | N10: 2 | O10: 126 | P10: 20 | Q10: 106 | R10: 19 | S10: 14 | T10: 1585 | U10: 44 | V10: 6 | W10: 40 | X10: 6 | Y10: 22 | Z10: 12 | AA10: 42 | AB10: 27 | AC10: 18 | AD10: 7 | AE10: 28 | AF10: 64 | AG10: 5 | AH10: 43 | AI10: 16 | AJ10: 88 | AK10: 18 | AL10: 4 | AM10: 6 | AN10: 15 | AO10: 1 | AP10: 60 | AQ10: 39 | AR10: 1 | AS10: 36 | AT10: 23 | AU10: 8 | AV10: 7 | AW10: 5 | AX10: 47 | AY10: 20 | AZ10: 40 | BA10: 68 | BB10: 45 | BC10: 62 | BD10: 82 | BE10: 53 | BF10: 56 | BG10: 71 | BH10: 144 | BI10: 91 | BJ10: 235 | BK10: 21 | BL10: 15
A11: Tatura | B11: 7 | C11: Home & away | D11: W | E11: 425 | F11: 273 | G11: 152 | H11: 137 | I11: 87 | J11: 24 | K11: 63 | L11: 67 | M11: 50 | N11: 9 | O11: 161 | P11: 19 | Q11: 142 | R11: 19 | S11: 29 | T11: 2088 | U11: 44 | V11: 8 | W11: 42 | X11: 10 | Y11: 18 | Z11: 14 | AA11: 63 | AB11: 28 | AC11: 16 | AD11: 6 | AE11: 29 | AF11: 59 | AG11: 4 | AH11: 23 | AI11: 32 | AJ11: 98 | AK11: 20 | AL11: 9 | AM11: 4 | AN11: 10 | AO11: 9 | AP11: 65 | AQ11: 47 | AR11: 18 | AS11: 34 | AT11: 13 | AU11: 20 | AV11: 14 | AW11: 1 | AX11: 55 | AY11: 35 | AZ11: 57 | BA11: 77 | BB11: 52 | BC11: 72 | BD11: 86 | BE11: 88 | BF11: 79 | BG11: 83 | BH11: 197 | BI11: 132 | BJ11: 329 | BK11: 37 | BL11: 22
A12: Kyabram | B12: 8 | C12: Home & away | D12: W | E12: 359 | F12: 219 | G12: 140 | H12: 107 | I12: 68 | J12: 31 | K12: 37 | L12: 61 | M12: 61 | N12: 10 | O12: 109 | P12: 10 | Q12: 99 | R12: 14 | S12: 18 | T12: 1657 | U12: 47 | V12: 7 | W12: 45 | X12: 11 | Y12: 20 | Z12: 14 | AA12: 48 | AB12: 37 | AC12: 16 | AD12: 7 | AE12: 72 | AF12: 63 | AG12: 4 | AH12: 41 | AI12: 18 | AJ12: 101 | AK12: 40 | AL12: 18 | AM12: 3 | AN12: 30 | AO12: 2 | AP12: 40 | AQ12: 33 | AR12: 4 | AS12: 28 | AT12: 8 | AU12: 10 | AV12: 14 | AW12: 5 | AX12: 60 | AY12: 29 | AZ12: 34 | BA12: 69 | BB12: 48 | BC12: 64 | BD12: 77 | BE12: 60 | BF12: 70 | BG12: 86 | BH12: 140 | BI12: 109 | BJ12: 249 | BK12: 27 | BL12: 26
A13: Benalla | B13: 9 | C13: Home & away | D13: W | E13: 406 | F13: 262 | G13: 144 | H13: 103 | I13: 64 | J13: 30 | K13: 34 | L13: 76 | M13: 63 | N13: 11 | O13: 149 | P13: 8 | Q13: 141 | R13: 14 | S13: 21 | T13: 1932 | U13: 39 | V13: 11 | W13: 38 | X13: 16 | Y13: 15 | Z13: 7 | AA13: 61 | AB13: 24 | AC13: 21 | AD13: 4 | AE13: 42 | AF13: 68 | AG13: 2 | AH13: 30 | AI13: 36 | AJ13: 112 | AK13: 42 | AL13: 5 | AM13: 3 | AN13: 21 | AO13: 9 | AP13: 62 | AQ13: 45 | AR13: 15 | AS13: 43 | AT13: 4 | AU13: 22 | AV13: 6 | AW13: 4 | AX13: 52 | AY13: 32 | AZ13: 68 | BA13: 81 | BB13: 62 | BC13: 78 | BD13: 85 | BE13: 74 | BF13: 92 | BG13: 100 | BH13: 205 | BI13: 123 | BJ13: 328 | BK13: 28 | BL13: 22
